Traceback (most recent call last):
  File "/app/src/migrate.py", line 380, in <module>
    exit(main(sys.argv[1:]))
         ^^^^^^^^^^^^^^^^^^
  File "/app/src/migrate.py", line 358, in main
    if not dbExport(Settings, srcMode, srcDb, srcDbFiles, isExportMode):
           ^^^^^^^^^^^^^^^^^^^^^^^^^^^^^^^^^^^^^^^^^^^^^^^^^^^^^^^^^^^^
  File "/app/src/migrate.py", line 160, in dbExport
    (client, allDatabases) = connect(Settings)
                             ^^^^^^^^^^^^^^^^^
  File "/app/src/migrate.py", line 127, in connect
    return (client, set(client.list_database_names()))
                        ^^^^^^^^^^^^^^^^^^^^^^^^^^^^
  File "/usr/local/lib/python3.11/site-packages/pymongo/mongo_client.py", line 1981, in list_database_names
    return [doc["name"] for doc in self.list_databases(session, nameOnly=True, comment=comment)]
                                   ^^^^^^^^^^^^^^^^^^^^^^^^^^^^^^^^^^^^^^^^^^^^^^^^^^^^^^^^^^^^
  File "/usr/local/lib/python3.11/site-packages/pymongo/mongo_client.py", line 1955, in list_databases
    res = admin._retryable_read_command(cmd, session=session, operation=_Op.LIST_DATABASES)
          ^^^^^^^^^^^^^^^^^^^^^^^^^^^^^^^^^^^^^^^^^^^^^^^^^^^^^^^^^^^^^^^^^^^^^^^^^^^^^^^^^
  File "/usr/local/lib/python3.11/site-packages/pymongo/database.py", line 1034, in _retryable_read_command
    return self.__client._retryable_read(_cmd, read_preference, session, operation)
           ^^^^^^^^^^^^^^^^^^^^^^^^^^^^^^^^^^^^^^^^^^^^^^^^^^^^^^^^^^^^^^^^^^^^^^^^
  File "/usr/local/lib/python3.11/site-packages/pymongo/mongo_client.py", line 1534, in _retryable_read
    return self._retry_internal(
           ^^^^^^^^^^^^^^^^^^^^^
  File "/usr/local/lib/python3.11/site-packages/pymongo/_csot.py", line 108, in csot_wrapper
    return func(self, *args, **kwargs)
           ^^^^^^^^^^^^^^^^^^^^^^^^^^^
  File "/usr/local/lib/python3.11/site-packages/pymongo/mongo_client.py", line 1501, in _retry_internal
    ).run()
      ^^^^^
  File "/usr/local/lib/python3.11/site-packages/pymongo/mongo_client.py", line 2347, in run
    return self._read() if self._is_read else self._write()
           ^^^^^^^^^^^^
  File "/usr/local/lib/python3.11/site-packages/pymongo/mongo_client.py", line 2477, in _read
    self._server = self._get_server()
                   ^^^^^^^^^^^^^^^^^^
  File "/usr/local/lib/python3.11/site-packages/pymongo/mongo_client.py", line 2433, in _get_server
    return self._client._select_server(
           ^^^^^^^^^^^^^^^^^^^^^^^^^^^^
  File "/usr/local/lib/python3.11/site-packages/pymongo/mongo_client.py", line 1316, in _select_server
    server = topology.select_server(
             ^^^^^^^^^^^^^^^^^^^^^^^
  File "/usr/local/lib/python3.11/site-packages/pymongo/topology.py", line 369, in select_server
    server = self._select_server(
             ^^^^^^^^^^^^^^^^^^^^
  File "/usr/local/lib/python3.11/site-packages/pymongo/topology.py", line 347, in _select_server
    servers = self.select_servers(
              ^^^^^^^^^^^^^^^^^^^^
  File "/usr/local/lib/python3.11/site-packages/pymongo/topology.py", line 254, in select_servers
    server_descriptions = self._select_servers_loop(
                          ^^^^^^^^^^^^^^^^^^^^^^^^^^
  File "/usr/local/lib/python3.11/site-packages/pymongo/topology.py", line 304, in _select_servers_loop
    raise ServerSelectionTimeoutError(
pymongo.errors.ServerSelectionTimeoutError: localhost:37017: [Errno 111] Connection refused (configured timeouts: socketTimeoutMS: 20000.0ms, connectTimeoutMS: 20000.0ms), Timeout: 30s, Topology Description: <TopologyDescription id: 663b79aae121d141ed98175a, topology_type: Unknown, servers: [<ServerDescription ('localhost', 37017) server_type: Unknown, rtt: None, error=AutoReconnect('localhost:37017: [Errno 111] Connection refused (configured timeouts: socketTimeoutMS: 20000.0ms, connectTimeoutMS: 20000.0ms)')>]>
